2023-05-21 18:24:09,549 - ERROR - Ошибка: 
Traceback (most recent call last):
  File "/root/Bot/LMTasks/base.py", line 237, in main
    choice = int(input("Введите номер таблицы (или 0 для выхода): "))
EOFError
2023-05-22 09:13:41,702 - INFO - Объект с ID 1669785252 успешно обновлен в таблице 'Users'.
2023-05-22 09:14:40,855 - INFO - Таблица 'Tasks' успешно экспортирована в файл 'Tasks.csv'.
